When you run managed ingestion it tries to create a python virtual environment for every run and it tries to install the needed packages there.

The above actions only take place when manual run was invoked.  

Logs output as follows:

```text
[2022-12-22 07:13:24,909] DEBUG    {acryl.executor.dispatcher.default_dispatcher:57} - Started thread <Thread(Thread-2 (dispatch_async), started 140078300452608)> for a01a6d82-08a4-418b-a064-7fa4108e100e
[2022-12-22 07:13:24,939] DEBUG    {acryl.executor.execution.default_executor:121} - Task for a01a6d82-08a4-418b-a064-7fa4108e100e created
[2022-12-22 07:13:24,948] INFO     {acryl.executor.execution.sub_process_ingestion_task:87} - Starting ingestion subprocess for exec_id=a01a6d82-08a4-418b-a064-7fa4108e100e (mysql)
[2022-12-22 07:26:05,239] INFO     {acryl.executor.execution.sub_process_ingestion_task:180} - Detected subprocess exited exec_id=a01a6d82-08a4-418b-a064-7fa4108e100e
[2022-12-22 07:26:05,239] INFO     {acryl.executor.execution.sub_process_ingestion_task:120} - Got EOF from subprocess exec_id=a01a6d82-08a4-418b-a064-7fa4108e100e - stopping log monitor
[2022-12-22 07:26:05,302] INFO     {acryl.executor.execution.sub_process_ingestion_task:154} - Detected subprocess return code exec_id=a01a6d82-08a4-418b-a064-7fa4108e100e - stopping logs reporting
[2022-12-22 07:26:05,324] DEBUG    {acryl.executor.execution.default_executor:137} - Cleaned up task for a01a6d82-08a4-418b-a064-7fa4108e100e
No user action configurations found. Not starting user actions.
2022-12-22 07:13:24.935165 [exec_id=a01a6d82-08a4-418b-a064-7fa4108e100e] INFO: Starting execution for task with name=RUN_INGEST
[a01a6d82-08a4-418b-a064-7fa4108e100e logs] venv doesn't exist.. minting..
[a01a6d82-08a4-418b-a064-7fa4108e100e logs] Requirement already satisfied: pip in /tmp/datahub/ingest/venv-mysql-0.9.2/lib/python3.10/site-packages (22.2.2)
[a01a6d82-08a4-418b-a064-7fa4108e100e logs] WARNING: Retrying (Retry(total=4, connect=None, read=None, redirect=None, status=None)) after connection broken by 'ConnectTimeoutError(<pip._vendor.urllib3.connection.HTTPSConnection object at 0x7fb914a23520>, 'Connection to pypi.org timed out. (connect timeout=15)')': /simple/pip/
[a01a6d82-08a4-418b-a064-7fa4108e100e logs] WARNING: Retrying (Retry(total=3, connect=None, read=None, redirect=None, status=None)) after connection broken by 'ConnectTimeoutError(<pip._vendor.urllib3.connection.HTTPSConnection object at 0x7fb914a23820>, 'Connection to pypi.org timed out. (connect timeout=15)')': /simple/pip/
[a01a6d82-08a4-418b-a064-7fa4108e100e logs] WARNING: Retrying (Retry(total=2, connect=None, read=None, redirect=None, status=None)) after connection broken by 'ConnectTimeoutError(<pip._vendor.urllib3.connection.HTTPSConnection object at 0x7fb914a23b50>, 'Connection to pypi.org timed out. (connect timeout=15)')': /simple/pip/
[a01a6d82-08a4-418b-a064-7fa4108e100e logs] WARNING: Retrying (Retry(total=1, connect=None, read=None, redirect=None, status=None)) after connection broken by 'ConnectTimeoutError(<pip._vendor.urllib3.connection.HTTPSConnection object at 0x7fb914a23cd0>, 'Connection to pypi.org timed out. (connect timeout=15)')': /simple/pip/
[a01a6d82-08a4-418b-a064-7fa4108e100e logs] WARNING: Retrying (Retry(total=0, connect=None, read=None, redirect=None, status=None)) after connection broken by 'ConnectTimeoutError(<pip._vendor.urllib3.connection.HTTPSConnection object at 0x7fb914a23e50>, 'Connection to pypi.org timed out. (connect timeout=15)')': /simple/pip/
[a01a6d82-08a4-418b-a064-7fa4108e100e logs] WARNING: Retrying (Retry(total=4, connect=None, read=None, redirect=None, status=None)) after connection broken by 'ConnectTimeoutError(<pip._vendor.urllib3.connection.HTTPSConnection object at 0x7fb914a9b490>, 'Connection to pypi.org timed out. (connect timeout=15)')': /simple/wheel/
[a01a6d82-08a4-418b-a064-7fa4108e100e logs] WARNING: Retrying (Retry(total=3, connect=None, read=None, redirect=None, status=None)) after connection broken by 'ConnectTimeoutError(<pip._vendor.urllib3.connection.HTTPSConnection object at 0x7fb914a9b940>, 'Connection to pypi.org timed out. (connect timeout=15)')': /simple/wheel/
[a01a6d82-08a4-418b-a064-7fa4108e100e logs] WARNING: Retrying (Retry(total=2, connect=None, read=None, redirect=None, status=None)) after connection broken by 'ConnectTimeoutError(<pip._vendor.urllib3.connection.HTTPSConnection object at 0x7fb914a9bac0>, 'Connection to pypi.org timed out. (connect timeout=15)')': /simple/wheel/
[a01a6d82-08a4-418b-a064-7fa4108e100e logs] WARNING: Retrying (Retry(total=1, connect=None, read=None, redirect=None, status=None)) after connection broken by 'ConnectTimeoutError(<pip._vendor.urllib3.connection.HTTPSConnection object at 0x7fb914a9bc40>, 'Connection to pypi.org timed out. (connect timeout=15)')': /simple/wheel/
[a01a6d82-08a4-418b-a064-7fa4108e100e logs] WARNING: Retrying (Retry(total=0, connect=None, read=None, redirect=None, status=None)) after connection broken by 'ConnectTimeoutError(<pip._vendor.urllib3.connection.HTTPSConnection object at 0x7fb914a9bdc0>, 'Connection to pypi.org timed out. (connect timeout=15)')': /simple/wheel/
[a01a6d82-08a4-418b-a064-7fa4108e100e logs] ERROR: Could not find a version that satisfies the requirement wheel (from versions: none)
[a01a6d82-08a4-418b-a064-7fa4108e100e logs] ERROR: No matching distribution found for wheel
[a01a6d82-08a4-418b-a064-7fa4108e100e logs] WARNING: There was an error checking the latest version of pip.
```

Scheduler ingestion can avoid above problems.